[2025-02-26T11:34:58.131+0000] {local_task_job_runner.py:123} INFO - ::group::Pre task execution logs
[2025-02-26T11:34:58.153+0000] {taskinstance.py:2614} INFO - Dependencies all met for dep_context=non-requeueable deps ti=<TaskInstance: coingecko_ingestion_dag.store_raw_data_in_hdfs scheduled__2025-01-05T00:00:00+00:00 [queued]>
[2025-02-26T11:34:58.164+0000] {taskinstance.py:2614} INFO - Dependencies all met for dep_context=requeueable deps ti=<TaskInstance: coingecko_ingestion_dag.store_raw_data_in_hdfs scheduled__2025-01-05T00:00:00+00:00 [queued]>
[2025-02-26T11:34:58.165+0000] {taskinstance.py:2867} INFO - Starting attempt 2 of 2
[2025-02-26T11:34:58.185+0000] {taskinstance.py:2890} INFO - Executing <Task(PythonOperator): store_raw_data_in_hdfs> on 2025-01-05 00:00:00+00:00
[2025-02-26T11:34:58.191+0000] {standard_task_runner.py:72} INFO - Started process 102707 to run task
[2025-02-26T11:34:58.195+0000] {standard_task_runner.py:104} INFO - Running: ['airflow', 'tasks', 'run', 'coingecko_ingestion_dag', 'store_raw_data_in_hdfs', 'scheduled__2025-01-05T00:00:00+00:00', '--job-id', '56', '--raw', '--subdir', 'DAGS_FOLDER/2_ingest_coingecko.py', '--cfg-path', '/tmp/tmpqtu613je']
[2025-02-26T11:34:58.198+0000] {standard_task_runner.py:105} INFO - Job 56: Subtask store_raw_data_in_hdfs
[2025-02-26T11:34:58.246+0000] {task_command.py:467} INFO - Running <TaskInstance: coingecko_ingestion_dag.store_raw_data_in_hdfs scheduled__2025-01-05T00:00:00+00:00 [running]> on host abdeljalil-ThinkBook-14-G2-ITL
[2025-02-26T11:34:58.322+0000] {taskinstance.py:3134} INFO - Exporting env vars: AIRFLOW_CTX_DAG_OWNER='etudiant' AIRFLOW_CTX_DAG_ID='coingecko_ingestion_dag' AIRFLOW_CTX_TASK_ID='store_raw_data_in_hdfs' AIRFLOW_CTX_EXECUTION_DATE='2025-01-05T00:00:00+00:00' AIRFLOW_CTX_TRY_NUMBER='2' AIRFLOW_CTX_DAG_RUN_ID='scheduled__2025-01-05T00:00:00+00:00'
[2025-02-26T11:34:58.323+0000] {taskinstance.py:732} INFO - ::endgroup::
[2025-02-26T11:35:00.479+0000] {taskinstance.py:3313} ERROR - Task failed with exception
Traceback (most recent call last):
  File "/home/abdeljalil/airflow/dags/2_ingest_coingecko.py", line 71, in store_in_hdfs
    subprocess.run(["hdfs", "dfs", "-mkdir", "-p", hdfs_dir], check=True)
  File "/usr/lib/python3.12/subprocess.py", line 571, in run
    raise CalledProcessError(retcode, process.args,
subprocess.CalledProcessError: Command '['hdfs', 'dfs', '-mkdir', '-p', '/user/etudiant/crypto/raw/YYYY=2025/MM=01/DD=05']' returned non-zero exit status 1.

During handling of the above exception, another exception occurred:

Traceback (most recent call last):
  File "/home/abdeljalil/.local/lib/python3.12/site-packages/airflow/models/taskinstance.py", line 768, in _execute_task
    result = _execute_callable(context=context, **execute_callable_kwargs)
             ^^^^^^^^^^^^^^^^^^^^^^^^^^^^^^^^^^^^^^^^^^^^^^^^^^^^^^^^^^^^^
  File "/home/abdeljalil/.local/lib/python3.12/site-packages/airflow/models/taskinstance.py", line 734, in _execute_callable
    return ExecutionCallableRunner(
           ^^^^^^^^^^^^^^^^^^^^^^^^
  File "/home/abdeljalil/.local/lib/python3.12/site-packages/airflow/utils/operator_helpers.py", line 252, in run
    return self.func(*args, **kwargs)
           ^^^^^^^^^^^^^^^^^^^^^^^^^^
  File "/home/abdeljalil/.local/lib/python3.12/site-packages/airflow/models/baseoperator.py", line 424, in wrapper
    return func(self, *args, **kwargs)
           ^^^^^^^^^^^^^^^^^^^^^^^^^^^
  File "/home/abdeljalil/.local/lib/python3.12/site-packages/airflow/operators/python.py", line 238, in execute
    return_value = self.execute_callable()
                   ^^^^^^^^^^^^^^^^^^^^^^^
  File "/home/abdeljalil/.local/lib/python3.12/site-packages/airflow/operators/python.py", line 256, in execute_callable
    return runner.run(*self.op_args, **self.op_kwargs)
           ^^^^^^^^^^^^^^^^^^^^^^^^^^^^^^^^^^^^^^^^^^^
  File "/home/abdeljalil/.local/lib/python3.12/site-packages/airflow/utils/operator_helpers.py", line 252, in run
    return self.func(*args, **kwargs)
           ^^^^^^^^^^^^^^^^^^^^^^^^^^
  File "/home/abdeljalil/airflow/dags/2_ingest_coingecko.py", line 75, in store_in_hdfs
    raise Exception(f"HDFS operation failed: {e}")
Exception: HDFS operation failed: Command '['hdfs', 'dfs', '-mkdir', '-p', '/user/etudiant/crypto/raw/YYYY=2025/MM=01/DD=05']' returned non-zero exit status 1.
[2025-02-26T11:35:00.488+0000] {taskinstance.py:1226} INFO - Marking task as FAILED. dag_id=coingecko_ingestion_dag, task_id=store_raw_data_in_hdfs, run_id=scheduled__2025-01-05T00:00:00+00:00, execution_date=20250105T000000, start_date=20250226T113458, end_date=20250226T113500
[2025-02-26T11:35:00.526+0000] {taskinstance.py:341} INFO - ::group::Post task execution logs
[2025-02-26T11:35:00.526+0000] {standard_task_runner.py:124} ERROR - Failed to execute job 56 for task store_raw_data_in_hdfs (HDFS operation failed: Command '['hdfs', 'dfs', '-mkdir', '-p', '/user/etudiant/crypto/raw/YYYY=2025/MM=01/DD=05']' returned non-zero exit status 1.; 102707)
Traceback (most recent call last):
  File "/home/abdeljalil/airflow/dags/2_ingest_coingecko.py", line 71, in store_in_hdfs
    subprocess.run(["hdfs", "dfs", "-mkdir", "-p", hdfs_dir], check=True)
  File "/usr/lib/python3.12/subprocess.py", line 571, in run
    raise CalledProcessError(retcode, process.args,
subprocess.CalledProcessError: Command '['hdfs', 'dfs', '-mkdir', '-p', '/user/etudiant/crypto/raw/YYYY=2025/MM=01/DD=05']' returned non-zero exit status 1.

During handling of the above exception, another exception occurred:

Traceback (most recent call last):
  File "/home/abdeljalil/.local/lib/python3.12/site-packages/airflow/task/task_runner/standard_task_runner.py", line 117, in _start_by_fork
    ret = args.func(args, dag=self.dag)
          ^^^^^^^^^^^^^^^^^^^^^^^^^^^^^
  File "/home/abdeljalil/.local/lib/python3.12/site-packages/airflow/cli/cli_config.py", line 49, in command
    return func(*args, **kwargs)
           ^^^^^^^^^^^^^^^^^^^^^
  File "/home/abdeljalil/.local/lib/python3.12/site-packages/airflow/utils/cli.py", line 116, in wrapper
    return f(*args, **kwargs)
           ^^^^^^^^^^^^^^^^^^
  File "/home/abdeljalil/.local/lib/python3.12/site-packages/airflow/cli/commands/task_command.py", line 483, in task_run
    task_return_code = _run_task_by_selected_method(args, _dag, ti)
                       ^^^^^^^^^^^^^^^^^^^^^^^^^^^^^^^^^^^^^^^^^^^^
  File "/home/abdeljalil/.local/lib/python3.12/site-packages/airflow/cli/commands/task_command.py", line 256, in _run_task_by_selected_method
    return _run_raw_task(args, ti)
           ^^^^^^^^^^^^^^^^^^^^^^^
  File "/home/abdeljalil/.local/lib/python3.12/site-packages/airflow/cli/commands/task_command.py", line 341, in _run_raw_task
    return ti._run_raw_task(
           ^^^^^^^^^^^^^^^^^
  File "/home/abdeljalil/.local/lib/python3.12/site-packages/airflow/utils/session.py", line 97, in wrapper
    return func(*args, session=session, **kwargs)
           ^^^^^^^^^^^^^^^^^^^^^^^^^^^^^^^^^^^^^^
  File "/home/abdeljalil/.local/lib/python3.12/site-packages/airflow/models/taskinstance.py", line 3006, in _run_raw_task
    return _run_raw_task(
           ^^^^^^^^^^^^^^
  File "/home/abdeljalil/.local/lib/python3.12/site-packages/airflow/models/taskinstance.py", line 274, in _run_raw_task
    TaskInstance._execute_task_with_callbacks(
  File "/home/abdeljalil/.local/lib/python3.12/site-packages/airflow/models/taskinstance.py", line 3161, in _execute_task_with_callbacks
    result = self._execute_task(context, task_orig)
             ^^^^^^^^^^^^^^^^^^^^^^^^^^^^^^^^^^^^^^
  File "/home/abdeljalil/.local/lib/python3.12/site-packages/airflow/models/taskinstance.py", line 3185, in _execute_task
    return _execute_task(self, context, task_orig)
           ^^^^^^^^^^^^^^^^^^^^^^^^^^^^^^^^^^^^^^^
  File "/home/abdeljalil/.local/lib/python3.12/site-packages/airflow/models/taskinstance.py", line 768, in _execute_task
    result = _execute_callable(context=context, **execute_callable_kwargs)
             ^^^^^^^^^^^^^^^^^^^^^^^^^^^^^^^^^^^^^^^^^^^^^^^^^^^^^^^^^^^^^
  File "/home/abdeljalil/.local/lib/python3.12/site-packages/airflow/models/taskinstance.py", line 734, in _execute_callable
    return ExecutionCallableRunner(
           ^^^^^^^^^^^^^^^^^^^^^^^^
  File "/home/abdeljalil/.local/lib/python3.12/site-packages/airflow/utils/operator_helpers.py", line 252, in run
    return self.func(*args, **kwargs)
           ^^^^^^^^^^^^^^^^^^^^^^^^^^
  File "/home/abdeljalil/.local/lib/python3.12/site-packages/airflow/models/baseoperator.py", line 424, in wrapper
    return func(self, *args, **kwargs)
           ^^^^^^^^^^^^^^^^^^^^^^^^^^^
  File "/home/abdeljalil/.local/lib/python3.12/site-packages/airflow/operators/python.py", line 238, in execute
    return_value = self.execute_callable()
                   ^^^^^^^^^^^^^^^^^^^^^^^
  File "/home/abdeljalil/.local/lib/python3.12/site-packages/airflow/operators/python.py", line 256, in execute_callable
    return runner.run(*self.op_args, **self.op_kwargs)
           ^^^^^^^^^^^^^^^^^^^^^^^^^^^^^^^^^^^^^^^^^^^
  File "/home/abdeljalil/.local/lib/python3.12/site-packages/airflow/utils/operator_helpers.py", line 252, in run
    return self.func(*args, **kwargs)
           ^^^^^^^^^^^^^^^^^^^^^^^^^^
  File "/home/abdeljalil/airflow/dags/2_ingest_coingecko.py", line 75, in store_in_hdfs
    raise Exception(f"HDFS operation failed: {e}")
Exception: HDFS operation failed: Command '['hdfs', 'dfs', '-mkdir', '-p', '/user/etudiant/crypto/raw/YYYY=2025/MM=01/DD=05']' returned non-zero exit status 1.
[2025-02-26T11:35:00.575+0000] {local_task_job_runner.py:266} INFO - Task exited with return code 1
[2025-02-26T11:35:00.591+0000] {taskinstance.py:3901} INFO - 0 downstream tasks scheduled from follow-on schedule check
[2025-02-26T11:35:00.593+0000] {local_task_job_runner.py:245} INFO - ::endgroup::
