[2025-02-26T11:31:06.087+0000] {local_task_job_runner.py:123} INFO - ::group::Pre task execution logs
[2025-02-26T11:31:06.103+0000] {taskinstance.py:2614} INFO - Dependencies all met for dep_context=non-requeueable deps ti=<TaskInstance: coingecko_ingestion_dag.fetch_data scheduled__2025-01-14T00:00:00+00:00 [queued]>
[2025-02-26T11:31:06.114+0000] {taskinstance.py:2614} INFO - Dependencies all met for dep_context=requeueable deps ti=<TaskInstance: coingecko_ingestion_dag.fetch_data scheduled__2025-01-14T00:00:00+00:00 [queued]>
[2025-02-26T11:31:06.114+0000] {taskinstance.py:2867} INFO - Starting attempt 1 of 2
[2025-02-26T11:31:06.134+0000] {taskinstance.py:2890} INFO - Executing <Task(PythonOperator): fetch_data> on 2025-01-14 00:00:00+00:00
[2025-02-26T11:31:06.140+0000] {standard_task_runner.py:72} INFO - Started process 97969 to run task
[2025-02-26T11:31:06.144+0000] {standard_task_runner.py:104} INFO - Running: ['airflow', 'tasks', 'run', 'coingecko_ingestion_dag', 'fetch_data', 'scheduled__2025-01-14T00:00:00+00:00', '--job-id', '43', '--raw', '--subdir', 'DAGS_FOLDER/2_ingest_coingecko.py', '--cfg-path', '/tmp/tmp8mvp9qs7']
[2025-02-26T11:31:06.146+0000] {standard_task_runner.py:105} INFO - Job 43: Subtask fetch_data
[2025-02-26T11:31:06.196+0000] {task_command.py:467} INFO - Running <TaskInstance: coingecko_ingestion_dag.fetch_data scheduled__2025-01-14T00:00:00+00:00 [running]> on host abdeljalil-ThinkBook-14-G2-ITL
[2025-02-26T11:31:06.283+0000] {taskinstance.py:3134} INFO - Exporting env vars: AIRFLOW_CTX_DAG_OWNER='etudiant' AIRFLOW_CTX_DAG_ID='coingecko_ingestion_dag' AIRFLOW_CTX_TASK_ID='fetch_data' AIRFLOW_CTX_EXECUTION_DATE='2025-01-14T00:00:00+00:00' AIRFLOW_CTX_TRY_NUMBER='1' AIRFLOW_CTX_DAG_RUN_ID='scheduled__2025-01-14T00:00:00+00:00'
[2025-02-26T11:31:06.284+0000] {taskinstance.py:732} INFO - ::endgroup::
[2025-02-26T11:31:06.644+0000] {taskinstance.py:3313} ERROR - Task failed with exception
Traceback (most recent call last):
  File "/home/abdeljalil/.local/lib/python3.12/site-packages/airflow/models/taskinstance.py", line 768, in _execute_task
    result = _execute_callable(context=context, **execute_callable_kwargs)
             ^^^^^^^^^^^^^^^^^^^^^^^^^^^^^^^^^^^^^^^^^^^^^^^^^^^^^^^^^^^^^
  File "/home/abdeljalil/.local/lib/python3.12/site-packages/airflow/models/taskinstance.py", line 734, in _execute_callable
    return ExecutionCallableRunner(
           ^^^^^^^^^^^^^^^^^^^^^^^^
  File "/home/abdeljalil/.local/lib/python3.12/site-packages/airflow/utils/operator_helpers.py", line 252, in run
    return self.func(*args, **kwargs)
           ^^^^^^^^^^^^^^^^^^^^^^^^^^
  File "/home/abdeljalil/.local/lib/python3.12/site-packages/airflow/models/baseoperator.py", line 424, in wrapper
    return func(self, *args, **kwargs)
           ^^^^^^^^^^^^^^^^^^^^^^^^^^^
  File "/home/abdeljalil/.local/lib/python3.12/site-packages/airflow/operators/python.py", line 238, in execute
    return_value = self.execute_callable()
                   ^^^^^^^^^^^^^^^^^^^^^^^
  File "/home/abdeljalil/.local/lib/python3.12/site-packages/airflow/operators/python.py", line 256, in execute_callable
    return runner.run(*self.op_args, **self.op_kwargs)
           ^^^^^^^^^^^^^^^^^^^^^^^^^^^^^^^^^^^^^^^^^^^
  File "/home/abdeljalil/.local/lib/python3.12/site-packages/airflow/utils/operator_helpers.py", line 252, in run
    return self.func(*args, **kwargs)
           ^^^^^^^^^^^^^^^^^^^^^^^^^^
  File "/home/abdeljalil/airflow/dags/2_ingest_coingecko.py", line 27, in fetch_coingecko_data
    raise Exception(f"API request failed with status {response.status_code}")
Exception: API request failed with status 429
[2025-02-26T11:31:06.657+0000] {taskinstance.py:1226} INFO - Marking task as UP_FOR_RETRY. dag_id=coingecko_ingestion_dag, task_id=fetch_data, run_id=scheduled__2025-01-14T00:00:00+00:00, execution_date=20250114T000000, start_date=20250226T113106, end_date=20250226T113106
[2025-02-26T11:31:06.706+0000] {taskinstance.py:341} INFO - ::group::Post task execution logs
[2025-02-26T11:31:06.706+0000] {standard_task_runner.py:124} ERROR - Failed to execute job 43 for task fetch_data (API request failed with status 429; 97969)
Traceback (most recent call last):
  File "/home/abdeljalil/.local/lib/python3.12/site-packages/airflow/task/task_runner/standard_task_runner.py", line 117, in _start_by_fork
    ret = args.func(args, dag=self.dag)
          ^^^^^^^^^^^^^^^^^^^^^^^^^^^^^
  File "/home/abdeljalil/.local/lib/python3.12/site-packages/airflow/cli/cli_config.py", line 49, in command
    return func(*args, **kwargs)
           ^^^^^^^^^^^^^^^^^^^^^
  File "/home/abdeljalil/.local/lib/python3.12/site-packages/airflow/utils/cli.py", line 116, in wrapper
    return f(*args, **kwargs)
           ^^^^^^^^^^^^^^^^^^
  File "/home/abdeljalil/.local/lib/python3.12/site-packages/airflow/cli/commands/task_command.py", line 483, in task_run
    task_return_code = _run_task_by_selected_method(args, _dag, ti)
                       ^^^^^^^^^^^^^^^^^^^^^^^^^^^^^^^^^^^^^^^^^^^^
  File "/home/abdeljalil/.local/lib/python3.12/site-packages/airflow/cli/commands/task_command.py", line 256, in _run_task_by_selected_method
    return _run_raw_task(args, ti)
           ^^^^^^^^^^^^^^^^^^^^^^^
  File "/home/abdeljalil/.local/lib/python3.12/site-packages/airflow/cli/commands/task_command.py", line 341, in _run_raw_task
    return ti._run_raw_task(
           ^^^^^^^^^^^^^^^^^
  File "/home/abdeljalil/.local/lib/python3.12/site-packages/airflow/utils/session.py", line 97, in wrapper
    return func(*args, session=session, **kwargs)
           ^^^^^^^^^^^^^^^^^^^^^^^^^^^^^^^^^^^^^^
  File "/home/abdeljalil/.local/lib/python3.12/site-packages/airflow/models/taskinstance.py", line 3006, in _run_raw_task
    return _run_raw_task(
           ^^^^^^^^^^^^^^
  File "/home/abdeljalil/.local/lib/python3.12/site-packages/airflow/models/taskinstance.py", line 274, in _run_raw_task
    TaskInstance._execute_task_with_callbacks(
  File "/home/abdeljalil/.local/lib/python3.12/site-packages/airflow/models/taskinstance.py", line 3161, in _execute_task_with_callbacks
    result = self._execute_task(context, task_orig)
             ^^^^^^^^^^^^^^^^^^^^^^^^^^^^^^^^^^^^^^
  File "/home/abdeljalil/.local/lib/python3.12/site-packages/airflow/models/taskinstance.py", line 3185, in _execute_task
    return _execute_task(self, context, task_orig)
           ^^^^^^^^^^^^^^^^^^^^^^^^^^^^^^^^^^^^^^^
  File "/home/abdeljalil/.local/lib/python3.12/site-packages/airflow/models/taskinstance.py", line 768, in _execute_task
    result = _execute_callable(context=context, **execute_callable_kwargs)
             ^^^^^^^^^^^^^^^^^^^^^^^^^^^^^^^^^^^^^^^^^^^^^^^^^^^^^^^^^^^^^
  File "/home/abdeljalil/.local/lib/python3.12/site-packages/airflow/models/taskinstance.py", line 734, in _execute_callable
    return ExecutionCallableRunner(
           ^^^^^^^^^^^^^^^^^^^^^^^^
  File "/home/abdeljalil/.local/lib/python3.12/site-packages/airflow/utils/operator_helpers.py", line 252, in run
    return self.func(*args, **kwargs)
           ^^^^^^^^^^^^^^^^^^^^^^^^^^
  File "/home/abdeljalil/.local/lib/python3.12/site-packages/airflow/models/baseoperator.py", line 424, in wrapper
    return func(self, *args, **kwargs)
           ^^^^^^^^^^^^^^^^^^^^^^^^^^^
  File "/home/abdeljalil/.local/lib/python3.12/site-packages/airflow/operators/python.py", line 238, in execute
    return_value = self.execute_callable()
                   ^^^^^^^^^^^^^^^^^^^^^^^
  File "/home/abdeljalil/.local/lib/python3.12/site-packages/airflow/operators/python.py", line 256, in execute_callable
    return runner.run(*self.op_args, **self.op_kwargs)
           ^^^^^^^^^^^^^^^^^^^^^^^^^^^^^^^^^^^^^^^^^^^
  File "/home/abdeljalil/.local/lib/python3.12/site-packages/airflow/utils/operator_helpers.py", line 252, in run
    return self.func(*args, **kwargs)
           ^^^^^^^^^^^^^^^^^^^^^^^^^^
  File "/home/abdeljalil/airflow/dags/2_ingest_coingecko.py", line 27, in fetch_coingecko_data
    raise Exception(f"API request failed with status {response.status_code}")
Exception: API request failed with status 429
[2025-02-26T11:31:06.758+0000] {local_task_job_runner.py:266} INFO - Task exited with return code 1
[2025-02-26T11:31:06.782+0000] {taskinstance.py:3901} INFO - 0 downstream tasks scheduled from follow-on schedule check
[2025-02-26T11:31:06.783+0000] {local_task_job_runner.py:245} INFO - ::endgroup::
